2025-02-22 03:38:36,608 INFO - helpers.log_helper - Completed configuring logger.
2025-02-22 03:38:36,608 INFO - __main__ - Python version is 3.12.7
2025-02-22 03:38:36,609 INFO - __main__ - Current commit of code: ___
2025-02-22 03:38:36,610 INFO - __main__ - Configuration parameters: {'encoder_type': 'TransformerEncoder', 'hidden_dim': 64, 'num_heads': 16, 'num_stacks': 6, 'residual': False, 'decoder_type': 'SingleLayerDecoder', 'decoder_activation': 'tanh', 'decoder_hidden_dim': 16, 'use_bias': False, 'use_bias_constant': False, 'bias_initial_value': False, 'batch_size': 64, 'input_dimension': 64, 'max_length': 12, 'data_size': 5000, 'read_data': True, 'data_path': 'input_data_path', 'normalize': False, 'transpose': True, 'score_type': 'BIC', 'reg_type': 'LR', 'lambda_iter_num': 1000, 'lambda_flag_default': True, 'score_bd_tight': True, 'lambda1_update': 1, 'lambda2_update': 10, 'score_lower': 0.0, 'score_upper': 0.0, 'lambda2_lower': -1, 'lambda2_upper': -1, 'seed': 8, 'nb_epoch': 20000, 'lr1_start': 0.001, 'lr1_decay_step': 5000, 'lr1_decay_rate': 0.96, 'alpha': 0.99, 'init_baseline': -1.0, 'temperature': 3.0, 'C': 10.0, 'l1_graph_reg': 0.0, 'inference_mode': True, 'restore_model': False, 'save_to': '20/model', 'restore_from': '20/model', 'log_dir': 'summary/20/repo', 'verbose': False, 'save_model_path': 'output/2025-02-22_03-38-36-608/model', 'summary_dir': 'output/2025-02-22_03-38-36-608/summary', 'plot_dir': 'output/2025-02-22_03-38-36-608/plot', 'graph_dir': 'output/2025-02-22_03-38-36-608/graph'}
2025-02-22 03:38:36,971 INFO - __main__ - Original sl: 1.8920581223061064, su: 7.27337148003996, strue: 3.121694481976613
2025-02-22 03:38:36,971 INFO - __main__ - Transfomed sl: 1.8920581223061064, su: 7.27337148003996, lambda2: 0.0001, true: 1.1425058140345163
2025-02-22 03:38:36,996 CRITICAL - helpers.log_helper - Unhandled exception
Traceback (most recent call last):
  File "/Users/pardazbanumohammad/trustworthyAI/research/Causal Discovery with RL/src/main.py", line 317, in <module>
    main()
  File "/Users/pardazbanumohammad/trustworthyAI/research/Causal Discovery with RL/src/main.py", line 119, in main
    actor = Actor(config)
            ^^^^^^^^^^^^^
  File "/Users/pardazbanumohammad/trustworthyAI/research/Causal Discovery with RL/src/models/actor_graph.py", line 52, in __init__
    self.input_ = tf.placeholder(tf.float32, [self.batch_size, self.max_length, self.input_dimension],
                  ^^^^^^^^^^^^^^
AttributeError: module 'tensorflow' has no attribute 'placeholder'
2025-02-22 03:38:37,110 INFO - rpy2.rinterface_lib.embedded - Embedded R ended.
2025-02-22 03:38:37,110 INFO - rpy2.rinterface_lib.embedded - Embedded R already ended.
